Workbook

Sheet Raw_Data_Q1
A1: Month | B1: Total_income | C1: Total_expense | D1: Month_Num
A2: January | B2: 53000 | C2: 29700 | D2: 1
A3: February | B3: 45000 | C3: 29550 | D3: 2
A4: March | B4: 50000 | C4: 30050 | D4: 3
A5: April | B5: 45000 | C5: 32350 | D5: 4
A6: May | B6: 51000 | C6: 33900 | D6: 5
A7: June | B7: 45000 | C7: 32900 | D7: 6
A8: July | B8: 52000 | C8: 36800 | D8: 7
A9: August | B9: 45000 | C9: 35330 | D9: 8
A10: September | B10: 49500 | C10: 31680 | D10: 9
A11: October | B11: 45000 | C11: 31640 | D11: 10
A12: November | B12: 50500 | C12: 30150 | D12: 11
A13: December | B13: 54000 | C13: 40900 | D13: 12

Sheet Raw_Data_Q2
A1: Month | B1: Total_income | C1: Total_expense | D1: Monthly_savings
A2: January | B2: 53000 | C2: 29700 | D2: 23300
A3: February | B3: 45000 | C3: 29550 | D3: 15450
A4: March | B4: 50000 | C4: 30050 | D4: 19950
A5: April | B5: 45000 | C5: 32350 | D5: 12650
A6: May | B6: 51000 | C6: 33900 | D6: 17100
A7: June | B7: 45000 | C7: 32900 | D7: 12100
A8: July | B8: 52000 | C8: 36800 | D8: 15200
A9: August | B9: 45000 | C9: 35330 | D9: 9670
A10: September | B10: 49500 | C10: 31680 | D10: 17820
A11: October | B11: 45000 | C11: 31640 | D11: 13360
A12: November | B12: 50500 | C12: 30150 | D12: 20350
A13: December | B13: 54000 | C13: 40900 | D13: 13100

Sheet Raw_Data_Q3
A1: category_name | B1: total_amount
A2: Rent | B2: 144000
A3: Food | B3: 61400
A4: EMI | B4: 60000

Sheet Raw_Data_Q4
A1: Month | B1: category_id | C1: category_name | D1: planned_amount | E1: spent_amount | F1: overly_spent
A2: January | B2: 7 | C2: Entertainment | D2: 2000 | E2: 2100 | F2: 100
A3: February | B3: 9 | C3: Shopping | D3: 3000 | E3: 3200 | F3: 200
A4: March | B4: 7 | C4: Entertainment | D4: 2000 | E4: 2200 | F4: 200
A5: April | B5: 9 | C5: Shopping | D5: 3000 | E5: 3800 | F5: 800
A6: April | B6: 7 | C6: Entertainment | D6: 2500 | E6: 2900 | F6: 400
A7: April | B7: 8 | C7: Utilities | D7: 1500 | E7: 1550 | F7: 50
A8: May | B8: 7 | C8: Entertainment | D8: 2500 | E8: 3200 | F8: 700
A9: May | B9: 9 | C9: Shopping | D9: 3500 | E9: 4200 | F9: 700
A10: May | B10: 4 | C10: Food | D10: 5000 | E10: 5300 | F10: 300
A11: May | B11: 8 | C11: Utilities | D11: 1500 | E11: 1600 | F11: 100
A12: June | B12: 7 | C12: Entertainment | D12: 2500 | E12: 2900 | F12: 400
A13: June | B13: 4 | C13: Food | D13: 5000 | E13: 5250 | F13: 250
... A33: December | B33: 8 | C33: Utilities | D33: 1500 | E33: 1600 | F33: 100

Sheet Raw_Data_Q5
A1: Month | B1: Monthly_savings | C1: target_savings | D1: savings_gap
A2: January | B2: 23300 | C2: 8000 | D2: 15300
A3: February | B3: 15450 | C3: 8000 | D3: 7450
A4: March | B4: 19950 | C4: 8000 | D4: 11950
A5: April | B5: 12650 | C5: 8000 | D5: 4650
A6: May | B6: 17100 | C6: 8000 | D6: 9100
A7: June | B7: 12100 | C7: 8000 | D7: 4100
A8: July | B8: 15200 | C8: 9000 | D8: 6200
A9: August | B9: 9670 | C9: 9000 | D9: 670
A10: September | B10: 17820 | C10: 8000 | D10: 9820
A11: October | B11: 13360 | C11: 8000 | D11: 5360
A12: November | B12: 20350 | C12: 8000 | D12: 12350
A13: December | B13: 13100 | C13: 6000 | D13: 7100

Sheet Summary_Dashboard
A1: Personal Finance Tracker — 2024 Annual Summary
A3: Month | B3: Total_Income | C3: Total_Expense | D3: Monthly_Savings | E3: Savings_Rate
A4: January | B4: =VLOOKUP(A4, Raw_Data_Q1!$A:$C, 2, 0) -> 53000 | C4: =VLOOKUP(A4, Raw_Data_Q1!$A:$C, 3, 0) -> 29700 | D4: 23300 | E4: =ROUND((D4/B4)*100, 2) -> 43.96
A5: February | B5: =VLOOKUP(A5, Raw_Data_Q1!$A:$C, 2, 0) -> 45000 | C5: =VLOOKUP(A5, Raw_Data_Q1!$A:$C, 3, 0) -> 29550 | D5: 15450 | E5: =ROUND((D5/B5)*100, 2) -> 34.33
A6: March | B6: =VLOOKUP(A6, Raw_Data_Q1!$A:$C, 2, 0) -> 50000 | C6: =VLOOKUP(A6, Raw_Data_Q1!$A:$C, 3, 0) -> 30050 | D6: 19950 | E6: =ROUND((D6/B6)*100, 2) -> 39.9
A7: April | B7: =VLOOKUP(A7, Raw_Data_Q1!$A:$C, 2, 0) -> 45000 | C7: =VLOOKUP(A7, Raw_Data_Q1!$A:$C, 3, 0) -> 32350 | D7: 12650 | E7: =ROUND((D7/B7)*100, 2) -> 28.11
A8: May | B8: =VLOOKUP(A8, Raw_Data_Q1!$A:$C, 2, 0) -> 51000 | C8: =VLOOKUP(A8, Raw_Data_Q1!$A:$C, 3, 0) -> 33900 | D8: 17100 | E8: =ROUND((D8/B8)*100, 2) -> 33.53
A9: June | B9: =VLOOKUP(A9, Raw_Data_Q1!$A:$C, 2, 0) -> 45000 | C9: =VLOOKUP(A9, Raw_Data_Q1!$A:$C, 3, 0) -> 32900 | D9: 12100 | E9: =ROUND((D9/B9)*100, 2) -> 26.89
A10: July | B10: =VLOOKUP(A10, Raw_Data_Q1!$A:$C, 2, 0) -> 52000 | C10: =VLOOKUP(A10, Raw_Data_Q1!$A:$C, 3, 0) -> 36800 | D10: 15200 | E10: =ROUND((D10/B10)*100, 2) -> 29.23
A11: August | B11: =VLOOKUP(A11, Raw_Data_Q1!$A:$C, 2, 0) -> 45000 | C11: =VLOOKUP(A11, Raw_Data_Q1!$A:$C, 3, 0) -> 35330 | D11: 9670 | E11: =ROUND((D11/B11)*100, 2) -> 21.49
A12: September | B12: =VLOOKUP(A12, Raw_Data_Q1!$A:$C, 2, 0) -> 49500 | C12: =VLOOKUP(A12, Raw_Data_Q1!$A:$C, 3, 0) -> 31680 | D12: 17820 | E12: =ROUND((D12/B12)*100, 2) -> 36
A13: October | B13: =VLOOKUP(A13, Raw_Data_Q1!$A:$C, 2, 0) -> 45000 | C13: =VLOOKUP(A13, Raw_Data_Q1!$A:$C, 3, 0) -> 31640 | D13: 13360 | E13: =ROUND((D13/B13)*100, 2) -> 29.69
A14: November | B14: =VLOOKUP(A14, Raw_Data_Q1!$A:$C, 2, 0) -> 50500 | C14: =VLOOKUP(A14, Raw_Data_Q1!$A:$C, 3, 0) -> 30150 | D14: 20350 | E14: =ROUND((D14/B14)*100, 2) -> 40.3
A15: December | B15: =VLOOKUP(A15, Raw_Data_Q1!$A:$C, 2, 0) -> 54000 | C15: =VLOOKUP(A15, Raw_Data_Q1!$A:$C, 3, 0) -> 40900 | D15: 13100 | E15: =ROUND((D15/B15)*100, 2) -> 24.26
A16: Total / Average | B16: =SUM(B4:B15) -> 585000 | C16: =SUM(C4:C15) -> 394950 | D16: =SUM(D4:D15) -> 190050 | E16: =ROUND(AVERAGE(E4:E15),2) -> 32.31
A19: Budget vs Actual Spending — 2024
A21: Month | B21: Category | C21: Budgeted_Amount | D21: Actual_Spent | E21: Variance | F21: Variance % | G21: Status
A22: =Raw_Data_Q4!A2 -> January | B22: =Raw_Data_Q4!C2 -> Entertainment | C22: =Raw_Data_Q4!D2 -> 2000 | D22: =Raw_Data_Q4!E2 -> 2100 | E22: =D22-C22 -> 100 | F22: =ROUND((E22/C22)*100,2) -> 5 | G22: =IF(E22>0,"⚠️ Over Budget","✅ On Track") -> ⚠️ Over Budget
A23: =Raw_Data_Q4!A3 -> February | B23: =Raw_Data_Q4!C3 -> Shopping | C23: =Raw_Data_Q4!D3 -> 3000 | D23: =Raw_Data_Q4!E3 -> 3200 | E23: =D23-C23 -> 200 | F23: =ROUND((E23/C23)*100,2) -> 6.67 | G23: =IF(E23>0,"⚠️ Over Budget","✅ On Track") -> ⚠️ Over Budget
A24: =Raw_Data_Q4!A4 -> March | B24: =Raw_Data_Q4!C4 -> Entertainment | C24: =Raw_Data_Q4!D4 -> 2000 | D24: =Raw_Data_Q4!E4 -> 2200 | E24: =D24-C24 -> 200 | F24: =ROUND((E24/C24)*100,2) -> 10 | G24: =IF(E24>0,"⚠️ Over Budget","✅ On Track") -> ⚠️ Over Budget
A25: =Raw_Data_Q4!A5 -> April | B25: =Raw_Data_Q4!C5 -> Shopping | C25: =Raw_Data_Q4!D5 -> 3000 | D25: =Raw_Data_Q4!E5 -> 3800 | E25: =D25-C25 -> 800 | F25: =ROUND((E25/C25)*100,2) -> 26.67 | G25: =IF(E25>0,"⚠️ Over Budget","✅ On Track") -> ⚠️ Over Budget
A26: =Raw_Data_Q4!A6 -> April | B26: =Raw_Data_Q4!C6 -> Entertainment | C26: =Raw_Data_Q4!D6 -> 2500 | D26: =Raw_Data_Q4!E6 -> 2900 | E26: =D26-C26 -> 400 | F26: =ROUND((E26/C26)*100,2) -> 16 | G26: =IF(E26>0,"⚠️ Over Budget","✅ On Track") -> ⚠️ Over Budget
A27: =Raw_Data_Q4!A7 -> April | B27: =Raw_Data_Q4!C7 -> Utilities | C27: =Raw_Data_Q4!D7 -> 1500 | D27: =Raw_Data_Q4!E7 -> 1550 | E27: =D27-C27 -> 50 | F27: =ROUND((E27/C27)*100,2) -> 3.33 | G27: =IF(E27>0,"⚠️ Over Budget","✅ On Track") -> ⚠️ Over Budget
A28: =Raw_Data_Q4!A8 -> May | B28: =Raw_Data_Q4!C8 -> Entertainment | C28: =Raw_Data_Q4!D8 -> 2500 | D28: =Raw_Data_Q4!E8 -> 3200 | E28: =D28-C28 -> 700 | F28: =ROUND((E28/C28)*100,2) -> 28 | G28: =IF(E28>0,"⚠️ Over Budget","✅ On Track") -> ⚠️ Over Budget
A29: =Raw_Data_Q4!A9 -> May | B29: =Raw_Data_Q4!C9 -> Shopping | C29: =Raw_Data_Q4!D9 -> 3500 | D29: =Raw_Data_Q4!E9 -> 4200 | E29: =D29-C29 -> 700 | F29: =ROUND((E29/C29)*100,2) -> 20 | G29: =IF(E29>0,"⚠️ Over Budget","✅ On Track") -> ⚠️ Over Budget
A30: =Raw_Data_Q4!A10 -> May | B30: =Raw_Data_Q4!C10 -> Food | C30: =Raw_Data_Q4!D10 -> 5000 | D30: =Raw_Data_Q4!E10 -> 5300 | E30: =D30-C30 -> 300 | F30: =ROUND((E30/C30)*100,2) -> 6 | G30: =IF(E30>0,"⚠️ Over Budget","✅ On Track") -> ⚠️ Over Budget
A31: =Raw_Data_Q4!A11 -> May | B31: =Raw_Data_Q4!C11 -> Utilities | C31: =Raw_Data_Q4!D11 -> 1500 | D31: =Raw_Data_Q4!E11 -> 1600 | E31: =D31-C31 -> 100 | F31: =ROUND((E31/C31)*100,2) -> 6.67 | G31: =IF(E31>0,"⚠️ Over Budget","✅ On Track") -> ⚠️ Over Budget
A32: =Raw_Data_Q4!A12 -> June | B32: =Raw_Data_Q4!C12 -> Entertainment | C32: =Raw_Data_Q4!D12 -> 2500 | D32: =Raw_Data_Q4!E12 -> 2900 | E32: =D32-C32 -> 400 | F32: =ROUND((E32/C32)*100,2) -> 16 | G32: =IF(E32>0,"⚠️ Over Budget","✅ On Track") -> ⚠️ Over Budget
A33: =Raw_Data_Q4!A13 -> June | B33: =Raw_Data_Q4!C13 -> Food | C33: =Raw_Data_Q4!D13 -> 5000 | D33: =Raw_Data_Q4!E13 -> 5250 | E33: =D33-C33 -> 250 | F33: =ROUND((E33/C33)*100,2) -> 5 | G33: =IF(E33>0,"⚠️ Over Budget","✅ On Track") -> ⚠️ Over Budget
... A53: =Raw_Data_Q4!A33 -> December | B53: =Raw_Data_Q4!C33 -> Utilities | C53: =Raw_Data_Q4!D33 -> 1500 | D53: =Raw_Data_Q4!E33 -> 1600 | E53: =D53-C53 -> 100 | F53: =ROUND((E53/C53)*100,2) -> 6.67 | G53: =IF(E53>0,"⚠️ Over Budget","✅ On Track") -> ⚠️ Over Budget
A56: Label | B56: Formula | C56: Column1
A57: Months Goal Met | B57: COUNTIF(Status column, "✅ Goal Met")
A58: Months Goal Missed | B58: COUNTIF(Status column, "❌ Goal Missed")
A59: Best Saving Month | B59: INDEX(Month column, MATCH(MAX(Actual Savings column), Actual Savings column, 0))
A62: Savings Goal vs Actual — 2024
A64: Month | B64: Target_Savings | C64: Actual_Savings | D64: Difference | E64: Status
A65: =Raw_Data_Q5!A2 -> January | B65: =Raw_Data_Q5!C2 -> 8000 | C65: =Raw_Data_Q5!B2 -> 23300 | D65: =C65 - B65 -> 15300 | E65: =IF(D65>=0,"✅ Goal Met","❌ Goal Missed") -> ✅ Goal Met
A66: =Raw_Data_Q5!A3 -> February | B66: =Raw_Data_Q5!C3 -> 8000 | C66: =Raw_Data_Q5!B3 -> 15450 | D66: =C66 - B66 -> 7450 | E66: =IF(D66>=0,"✅ Goal Met","❌ Goal Missed") -> ✅ Goal Met
A67: =Raw_Data_Q5!A4 -> March | B67: =Raw_Data_Q5!C4 -> 8000 | C67: =Raw_Data_Q5!B4 -> 19950 | D67: =C67 - B67 -> 11950 | E67: =IF(D67>=0,"✅ Goal Met","❌ Goal Missed") -> ✅ Goal Met
A68: =Raw_Data_Q5!A5 -> April | B68: =Raw_Data_Q5!C5 -> 8000 | C68: =Raw_Data_Q5!B5 -> 12650 | D68: =C68 - B68 -> 4650 | E68: =IF(D68>=0,"✅ Goal Met","❌ Goal Missed") -> ✅ Goal Met
...
